Workbook

Sheet GA018(증권거래)
A3: 가.증권거래현황
D10: 매수 | E10: 매도 | G10: 시가액
A11: 계정명 | D11: 매수 | E11: 매도 | F11: 합계 | G11: 잔액 | H11: 평가손익
A12: 지분증권 | B12: 주식 | C12: 유가증권시장 | D12: 0 | E12: 0 | F12: =SUM(D12:E12) -> 0 | G12: 0 | H12: 0
C13: 코스닥시장 | D13: 0 | E13: 0 | F13: =SUM(D13:E13) -> 0 | G13: 0 | H13: 0
C14: 코넥스시장 | D14: 0 | E14: 0 | F14: =SUM(D14:E14) -> 0 | G14: 0 | H14: 0
C15: 기타 | D15: 0 | E15: 0 | F15: =SUM(D15:E15) -> 0 | G15: 0 | H15: 0
C16: 소계 | D16: =SUM(D12:D15) -> 0 | E16: =SUM(E12:E15) -> 0 | F16: =SUM(F12:F15) -> 0 | G16: =SUM(G12:G15) -> 0 | H16: =SUM(H12:H15) -> 0
B17: 신주인수권증권 | C17: 유가증권시장 | D17: 0 | E17: 0 | F17: =SUM(D17:E17) -> 0 | G17: 0 | H17: 0
C18: 코스닥시장 | D18: 0 | E18: 0 | F18: =SUM(D18:E18) -> 0 | G18: 0 | H18: 0
C19: 코넥스시장 | D19: 0 | E19: 0 | F19: =SUM(D19:E19) -> 0 | G19: 0 | H19: 0
C20: 기타 | D20: 0 | E20: 0 | F20: =SUM(D20:E20) -> 0 | G20: 0 | H20: 0
C21: 소계 | D21: =SUM(D17:D20) -> 0 | E21: =SUM(E17:E20) -> 0 | F21: =SUM(F17:F20) -> 0 | G21: =SUM(G17:G20) -> 0 | H21: 0
B22: 기타 | C22: 유가증권시장 | D22: 0 | E22: 0 | F22: 0 | G22: 0 | H22: 0
C23: 코스닥시장 | D23: 0 | E23: 0 | F23: 0 | G23: 0 | H23: 0
C24: 코넥스시장 | D24: 0 | E24: 0 | F24: 0 | G24: 0 | H24: 0
C25: 기타 | D25: 0 | E25: 0 | F25: 0 | G25: 0 | H25: 0
C26: 소계 | D26: =SUM(D22:D25) -> 0 | E26: =SUM(E22:E25) -> 0 | F26: =SUM(F22:F25) -> 0 | G26: =SUM(G22:G25) -> 0 | H26: =SUM(H17:H25) -> 0
B27: 계 | D27: =D16+D21+D26 -> 0 | E27: =E16+E21+E26 -> 0 | F27: =F16+F21+F26 -> 0 | G27: =G16+G21+G26 -> 0 | H27: =H16+H21+H26 -> 0
A28: 채무증권 | B28: 국채,지방채 | C28: 국고채 | D28: 0 | E28: 0 | F28: =SUM(D28:E28) -> 0 | G28: 0 | H28: 0
C29: 국민주택채권 | D29: 0 | E29: 0 | F29: =SUM(D29:E29) -> 0 | G29: 0 | H29: 0
C30: 기타 | D30: 0 | E30: 0 | F30: =SUM(D30:E30) -> 0 | G30: 0 | H30: 0
C31: 소계 | D31: =SUM(D28:D30) -> 0 | E31: =SUM(E28:E30) -> 0 | F31: =SUM(F28:F30) -> 0 | G31: =SUM(G28:G30) -> 0 | H31: =SUM(H28:H30) -> 0
B32: 특수채 | C32: 통화안정증권 | D32: 0 | E32: 0 | F32: =SUM(D32:E32) -> 0 | G32: 0 | H32: 0
C33: 예금보험공사채 | D33: 0 | E33: 0 | F33: =SUM(D33:E33) -> 0 | G33: 0 | H33: 0
C34: 토지개발채권 | D34: 0 | E34: 0 | F34: =SUM(D34:E34) -> 0 | G34: 0 | H34: 0
C35: 기타 | D35: 0 | E35: 0 | F35: =SUM(D35:E35) -> 0 | G35: 0 | H35: 0
C36: 소계 | D36: =SUM(D32:D35) -> 0 | E36: =SUM(E32:E35) -> 0 | F36: =SUM(F32:F35) -> 0 | G36: =SUM(G32:G35) -> 0 | H36: =SUM(H32:H35) -> 0
B37: 금융채 | C37: 산금채 | D37: 0 | E37: 0 | F37: =SUM(D37:E37) -> 0 | G37: 0 | H37: 0
C38: 중기채 | D38: 0 | E38: 0 | F38: =SUM(D38:E38) -> 0 | G38: 0 | H38: 0
C39: 은행채 | D39: 0 | E39: 0 | F39: =SUM(D39:E39) -> 0 | G39: 0 | H39: 0
C40: 여전채 | D40: 0 | E40: 0 | F40: =SUM(D40:E40) -> 0 | G40: 0 | H40: 0
C41: 종금채 | D41: 0 | E41: 0 | F41: =SUM(D41:E41) -> 0 | G41: 0 | H41: 0
C42: 기타 | D42: 0 | E42: 0 | F42: =SUM(D42:E42) -> 0 | G42: 0 | H42: 0
C43: 소계 | D43: =SUM(D37:D42) -> 0 | E43: =SUM(E37:E42) -> 0 | F43: =SUM(F37:F42) -> 0 | G43: =SUM(G37:G42) -> 0 | H43: =SUM(H37:H42) -> 0
B44: 회사채 | D44: 0 | E44: 0 | F44: =SUM(D44:E44) -> 0 | G44: 0 | H44: 0
B45: 기업어음증권 | D45: 0 | E45: 0 | F45: =SUM(D45:E45) -> 0 | G45: 0 | H45: 0
B46: 기타 | D46: 0 | E46: 0 | F46: =SUM(D46:E46) -> 0 | G46: 0 | H46: 0
B47: 계 | D47: =D31+D36+D43+D44+D45+D46 -> 0 | E47: =E31+E36+E43+E44+E45+E46 -> 0 | F47: =F31+F36+F43+F44+F45+F46 -> 0 | G47: =G31+G36+G43+G44+G45+G46 -> 0 | H47: =H31+H36+H43+H44+H45+H46 -> 0
A48: 집합투자증권 | B48: ETF | D48: 0 | E48: 0 | F48: =SUM(D48:E48) -> 0 | G48: 0 | H48: 0
...

Sheet GA025(손익)
A3: 다. 포괄손익계산서
A11: 계정명 | B11: 금액
A12: Ⅰ. 영업수익 | B12: =B13+B70+B123+B138+B164+B169+B172+B201 -> 0 | C12: 1
A13: 1. 수수료수익 | B13: =B14+B26+B27+B30+B34+B38+B39+B44+B48+B56+B60+B65+B66+B67+B68+B69 -> 0
A14: 1) 수탁수수료 | B14: 0
A15: ① 유가증권시장 | B15: 0
A16: ② 코스닥시장 | B16: 0
A17: ③ 파생상품시장 | B17: 0
A18: ④ 외화증권수탁 | B18: 0
A19: ⑤ 채권장외중개 | B19: 0
A20: ⑥ 전자장외증권시장 | B20: 0
A21: ⑦ 해외파생상품 | B21: 0
A22: ⑧ 기타 | B22: 0
A23: 2) 인수 및 주선수수료 | B23: 0
A24: ① 원화증권 | B24: 0
A25: ② 외화증권 | B25: 0
... A29: ② 판매보수 | B29: 0
A30: 5) 자산관리수수료 | B30: =B31+B32+B33 -> 0
A31: ① 투자자문 | B31: 0 | C31: 12 | D31: 수수료_과세
A32: ② 투자일임 | B32: 0 | C32: 12 | D32: 수수료_면세
A33: ③ 기타 | B33: 0
A34: 6) 집합투자기구운용보수 | B34: =SUM(B35) -> 0
A35: ① 투자신탁위탁자보수 | B35: 0 | C35: 12 | D35: 수수료
A36: ② 투자회사운용수수료수익 | B36: 0
A37: ③ 기타 | B37: 0
A38: 7) 어음지급보증료 | B38: 0
A39: 8) 매수및합병수수료 | B39: 0
A40: ① 평가수수료 | B40: 0
A41: ② 매수합병중개수수료 | B41: 0
A42: ③ 구조조정및금융상담수수료 | B42: 0
A43: ④ 기타 | B43: 0
A44: 9) 파생결합증권판매수수료 | B44: 0
A45: ① 주가연계증권 | B45: 0
A46: ② 주식워런트증권 | B46: 0
A47: ③ 기타 | B47: 0
... A69: 17) 기타 | B69: 0
A70: 2.증권평가 및 처분이익 | B70: =B71+B79+B86+B92+B96+B99+B103+B107+B111+B115+B119 -> 0
A71: 1) 당기손익-공정가치측정증권처분이익 | B71: =SUM(B72:B78) -> 0
A72: ① 주식처분이익 | B72: 0 | C72: 1
A73: ② 신주인수권증서처분이익 | B73: 0
...

Sheet GA023(재무)
A3: 가.재무상태표
A11: 계정명 | B11: 금액
A12: 자산총계 | B12: =B13+B55+B113+B137+B185+B204+B210+B214 -> 0
A13: Ⅰ. 현금 및 예치금 | B13: =B14+B25 -> 0
A14: 1. 현금 및 현금성 자산 | B14: =SUM(B15:B24) -> 0
A15: 1) 현금 | B15: 0 | C15: 1
A16: 2) 정기예.적금 | B16: 0
A17: 3) 보통예금 | B17: 0 | C17: 1
A18: 4) 당좌예금 | B18: 0
A19: 5) 외화예금 | B19: 0
A20: 6) 양도성예금증서 | B20: 0
A21: 7) MMDA | B21: 0
A22: 8) MMF | B22: 0 | C22: 1
A23: 9) 금융어음 | B23: 0
A24: 10) 기타 | B24: 0 | C24: 1
A25: 2. 예치금 | B25: =B26+B29+B33+B37+B38+B39+B44+B49+B50+B51+B52+B53+B54 -> 0
A26: 1) 청약예치금 | B26: =SUM(B27:B28) -> 0
A27: ① 자기분 | B27: 0 | C27: 1
A28: ② 투자자분 | B28: 0
A29: 2) 투자자예탁금별도예치금(예금) | B29: =SUM(B30:B32) -> 0
A30: ① 일반예수분 | B30: 0
A31: ② 장내파생상품거래분 | B31: 0
A32: ③ 집합투자증권투자자예수분 | B32: 0
A33: 3) 투자자예탁금별도예치금(신탁) | B33: =SUM(B34:B37) -> 0
A34: ① 일반예수분 | B34: 0
A35: ② 장내파생상품거래분 | B35: 0
A36: ③ 집합투자증권투자자예수분 | B36: 0
A37: 4) 대차거래이행보증금 | B37: 0
A38: 5) 매매예납금 | B38: 0
A39: 6) 장내파생상품거래예치금 | B39: =SUM(B40:B43) -> 0
A40: ① 자기분(국내) | B40: 0
A41: ② 자기분(해외) | B41: 0
A42: ③ 투자자분(국내) | B42: 0
A43: ④ 투자자분(해외) | B43: 0
A44: 7) 장내파생상품매매증거금 | B44: =SUM(B45:B48) -> 0
A45: ① 자기분(국내) | B45: 0
A46: ② 자기분(해외) | B46: 0
A47: ③ 투자자분(국내) | B47: 0
A48: ④ 투자자분(해외) | B48: 0
A49: 8) 유통금융차주담보금 | B49: 0
...

Sheet GA027(각주)
A1: 해당사항 없음
A3: 마.각주사항
A11: 계정명 | B11: 금액
A12: Ⅰ. 채무보증 | B12: 0
A13: 1. 지급보증 | B13: 0
A14: ① 사채지급보증 | B14: 0
A15: ② 자회사채무보증 | B15: 0
A16: ③ 신용파생상품 | B16: 0
A17: ④ 기타지급보증 | B17: 0
A18: ⑤ 어음지급보증(종금계정) | B18: 0
A19: ⑥ 기타지급보증(종금계정) | B19: 0
A20: 2. 매입보장약정 | B20: 0
A21: 3. 채무인수약정 | B21: 0
A22: 4. 매입확약 | B22: 0
A23: ① 대출확약 | B23: 0
... A111: 2. 무담보부 | B111: 0

Sheet GA032(건전성)
A1: 해당사항 없음
A3: 가.자산건전성분류현황
B11: 정상 | C11: 요주의 | D11: 고정 | E11: 회수의문 | F11: 추정손실 | G11: 합계
A12: 콜론 | B12: 0 | C12: 0 | D12: 0 | E12: 0 | F12: 0 | G12: 0
A13: 신용공여금 | B13: 0 | C13: 0 | D13: 0 | E13: 0 | F13: 0 | G13: 0
A14: 환매조건부매수 | B14: 0 | C14: 0 | D14: 0 | E14: 0 | F14: 0 | G14: 0
A15: 대여금 | B15: 0 | C15: 0 | D15: 0 | E15: 0 | F15: 0 | G15: 0
A16: 대출금 | B16: 0 | C16: 0 | D16: 0 | E16: 0 | F16: 0 | G16: 0
A17: (부동산PF관련) | B17: 0 | C17: 0 | D17: 0 | E17: 0 | F17: 0 | G17: 0
A18: 매입대출채권 | B18: 0 | C18: 0 | D18: 0 | E18: 0 | F18: 0 | G18: 0
A19: (부동산PF관련) | B19: 0 | C19: 0 | D19: 0 | E19: 0 | F19: 0 | G19: 0
A20: 대지급금 | B20: 0 | C20: 0 | D20: 0 | E20: 0 | F20: 0 | G20: 0
A21: 부도채권 | B21: 0 | C21: 0 | D21: 0 | E21: 0 | F21: 0 | G21: 0
A22: 부도어음 | B22: 0 | C22: 0 | D22: 0 | E22: 0 | F22: 0 | G22: 0
A23: 사모사채 | B23: 0 | C23: 0 | D23: 0 | E23: 0 | F23: 0 | G23: 0
... A39: (부동산PF관련계) | B39: 0 | C39: 0 | D39: 0 | E39: 0 | F39: 0 | G39: 0

Sheet GA262(범주)
A3: 자산·부채 범주별 분류
C11: A | D11: B | E11: C | F11: D | G11: F | H11: G | I11: H | J11: I
C12: 금융자산(부채) | H12: 기타 | I12: 매각예정비유동자산(부채) | J12: 합계
C13: 당기손익-공정가치측정금융자산(부채) | D13: 당기손익-공정가치측정지정금융자산(부채) | E13: 기타포괄손익-공정가치측정금융자산 | F13: 상각후원가측정금융자산 | G13: 상각후원가측정부채
A14: F100000000 | B14: 자산총계 | C14: =C15+C41+C65+C74+C114+C128+C134+C138 -> 0 | D14: 0 | E14: =E15+E41+E65+E74+E114+E128+E134+E138 -> 0 | F14: 0 | G14: 0 | H14: =H15+H41+H65+H74+H114+H128+H134+H138 -> 0 | I14: 0 | J14: =SUM(C14:I14) -> 0
A15: _x000D_ F110000000 | B15: Ⅰ. 현금 및 예치금 | C15: 0 | D15: 0 | E15: 0 | F15: 0 | G15: 0 | H15: =H16+H27 -> 0 | I15: 0 | J15: =SUM(C15:I15) -> 0
A16: _x000D_ F110100000 | B16: 1. 현금 및 현금성 자산 | C16: 0 | D16: 0 | E16: 0 | F16: 0 | G16: 0 | H16: =SUM(H17:H26) -> 0 | I16: 0 | J16: =SUM(C16:I16) -> 0
A17: _x000D_ F110101000 | B17: 1) 현금 | C17: 0 | D17: 0 | E17: 0 | F17: 0 | G17: 0 | H17: ='GA023(재무)'!B15 -> 0 | I17: 0 | J17: =SUM(C17:I17) -> 0
A18: _x000D_ F110102000 | B18: 2) 정기예·적금 | C18: 0 | D18: 0 | E18: 0 | F18: 0 | G18: 0 | H18: 0 | I18: 0 | J18: =SUM(C18:I18) -> 0
A19: _x000D_ F110103000 | B19: 3) 보통예금 | C19: 0 | D19: 0 | E19: 0 | F19: 0 | G19: 0 | H19: ='GA023(재무)'!B17 -> 0 | I19: 0 | J19: =SUM(C19:I19) -> 0
A20: _x000D_ F110104000 | B20: 4) 당좌예금 | C20: 0 | D20: 0 | E20: 0 | F20: 0 | G20: 0 | H20: 0 | I20: 0 | J20: =SUM(C20:I20) -> 0
A21: _x000D_ F110105000 | B21: 5) 외화예금 | C21: 0 | D21: 0 | E21: 0 | F21: 0 | G21: 0 | H21: 0 | I21: 0 | J21: =SUM(C21:I21) -> 0
A22: _x000D_ F110106000 | B22: 6) 양도성예금증서 | C22: 0 | D22: 0 | E22: 0 | F22: 0 | G22: 0 | H22: 0 | I22: 0 | J22: =SUM(C22:I22) -> 0
A23: _x000D_ F110107000 | B23: 7) MMDA | C23: 0 | D23: 0 | E23: 0 | F23: 0 | G23: 0 | H23: 0 | I23: 0 | J23: =SUM(C23:I23) -> 0
A24: _x000D_ F110108000 | B24: 8) MMF | C24: 0 | D24: 0 | E24: 0 | F24: 0 | G24: 0 | H24: ='GA023(재무)'!B22 -> 0 | I24: 0 | J24: =SUM(C24:I24) -> 0
A25: _x000D_ F110109000 | B25: 9) 금융어음 | C25: 0 | D25: 0 | E25: 0 | F25: 0 | G25: 0 | H25: 0 | I25: 0 | J25: =SUM(C25:I25) -> 0
A26: _x000D_ F110110000 | B26: 10) 기타 | C26: 0 | D26: 0 | E26: 0 | F26: 0 | G26: 0 | H26: ='GA023(재무)'!B24 -> 0 | I26: 0 | J26: =SUM(C26:I26) -> 0
A27: _x000D_ F110200000 | B27: 2. 예치금 | C27: 0 | D27: 0 | E27: 0 | F27: 0 | G27: 0 | H27: =SUM(H28:H40) -> 0 | I27: 0 | J27: =SUM(C27:I27) -> 0
A28: _x000D_ F110201000 | B28: 1) 청약예치금 | C28: 0 | D28: 0 | E28: 0 | F28: 0 | G28: 0 | H28: ='GA023(재무)'!B26 -> 0 | I28: 0 | J28: =SUM(C28:I28) -> 0
A29: _x000D_ F110202000 | B29: 2) 투자자예탁금별도예치금(예금) | C29: 0 | D29: 0 | E29: 0 | F29: 0 | G29: 0 | H29: 0 | I29: 0 | J29: =SUM(C29:I29) -> 0
A30: _x000D_ F110203000 | B30: 3) 투자자예탁금별도예치금(신탁) | C30: 0 | D30: 0 | E30: 0 | F30: 0 | G30: 0 | H30: 0 | I30: 0 | J30: =SUM(C30:I30) -> 0
A31: _x000D_ F110204000 | B31: 4) 대차거래이행보증금 | C31: 0 | D31: 0 | E31: 0 | F31: 0 | G31: 0 | H31: 0 | I31: 0 | J31: =SUM(C31:I31) -> 0
A32: _x000D_ F110205000 | B32: 5) 매매예납금 | C32: 0 | D32: 0 | E32: 0 | F32: 0 | G32: 0 | H32: 0 | I32: 0 | J32: =SUM(C32:I32) -> 0
A33: _x000D_ F110206000 | B33: 6) 장내파생상품거래예치금 | C33: 0 | D33: 0 | E33: 0 | F33: 0 | G33: 0 | H33: 0 | I33: 0 | J33: =SUM(C33:I33) -> 0
A34: _x000D_ F110207000 | B34: 7) 장내파생상품매매증거금 | C34: 0 | D34: 0 | E34: 0 | F34: 0 | G34: 0 | H34: 0 | I34: 0 | J34: =SUM(C34:I34) -> 0
A35: _x000D_ F110208000 | B35: 8) 유통금융차주담보금 | C35: 0 | D35: 0 | E35: 0 | F35: 0 | G35: 0 | H35: 0 | I35: 0 | J35: =SUM(C35:I35) -> 0
A36: _x000D_ F110209000 | B36: 9) 유통금융담보금 | C36: 0 | D36: 0 | E36: 0 | F36: 0 | G36: 0 | H36: 0 | I36: 0 | J36: =SUM(C36:I36) -> 0
A37: _x000D_ F110210000 | B37: 10) 장기성예금 | C37: 0 | D37: 0 | E37: 0 | F37: 0 | G37: 0 | H37: 0 | I37: 0 | J37: =SUM(C37:I37) -> 0
A38: _x000D_ F110211000 | B38: 11) 특정예금 등 | C38: 0 | D38: 0 | E38: 0 | F38: 0 | G38: 0 | H38: 0 | I38: 0 | J38: =SUM(C38:I38) -> 0
A39: _x000D_ F110212000 | B39: 12) 신탁공탁금 | C39: 0 | D39: 0 | E39: 0 | F39: 0 | G39: 0 | H39: 0 | I39: 0 | J39: =SUM(C39:I39) -> 0
A40: _x000D_ F110213000 | B40: 13) 기타 | C40: 0 | D40: 0 | E40: 0 | F40: 0 | G40: 0 | H40: 0 | I40: 0 | J40: =SUM(C40:I40) -> 0
A41: _x000D_ F120000000 | B41: Ⅱ. 증권 | C41: =C42+C56+C59 -> 0 | D41: 0 | E41: =E42+E56+E59 -> 0 | F41: 0 | G41: 0 | H41: =H42+H56 -> 0 | I41: 0 | J41: =SUM(C41:I41) -> 0
A42: _x000D_ F120100000 | B42: 1. 관계회사투자지분외의 증권 | C42: =SUM(C43:C55) -> 0 | D42: 0 | E42: =SUM(E43:E55) -> 0 | F42: 0 | G42: 0 | H42: 0 | I42: 0 | J42: =SUM(C42:I42) -> 0
A43: _x000D_ F120101000 | B43: 1) 주식 | C43: ='GA023(재무)'!B57 -> 0 | D43: 0 | E43: ='GA023(재무)'!B74 -> 0 | F43: 0 | G43: 0 | H43: 0 | I43: 0 | J43: =SUM(C43:I43) -> 0
A44: _x000D_ F120102000 | B44: 2) 출자금 | C44: 0 | D44: 0 | E44: 0 | F44: 0 | G44: 0 | H44: 0 | I44: 0 | J44: =SUM(C44:I44) -> 0
A45: _x000D_ F120103000 | B45: 3) 신주인수권증서 | C45: 0 | D45: 0 | E45: 0 | F45: 0 | G45: 0 | H45: 0 | I45: 0 | J45: =SUM(C45:I45) -> 0
A46: _x000D_ F120104000 | B46: 4) 국채·지방채 | C46: 0 | D46: 0 | E46: 0 | F46: 0 | G46: 0 | H46: 0 | I46: 0 | J46: =SUM(C46:I46) -> 0
A47: _x000D_ F120105000 | B47: 5) 특수채 | C47: 0 | D47: 0 | E47: 0 | F47: 0 | G47: 0 | H47: 0 | I47: 0 | J47: =SUM(C47:I47) -> 0
A48: _x000D_ F120106000 | B48: 6) 회사채 | C48: 0 | D48: 0 | E48: ='GA023(재무)'!B93 -> 0 | F48: 0 | G48: 0 | H48: 0 | I48: 0 | J48: =SUM(C48:I48) -> 0
A49: _x000D_ F120107000 | B49: 7) 집합투자증권 | C49: 0 | D49: 0 | E49: ='GA023(재무)'!B81 -> 0 | F49: 0 | G49: 0 | H49: 0 | I49: 0 | J49: =SUM(C49:I49) -> 0
...

Sheet GA040(유동성비율)
A3: 나. (1)유동성비율(2월)(투자매매·중개업)
C11: A1 | D11: B1 | E11: C
B12: 계정명 | C12: 전월말(①) | D12: 당기말(②) | E12: 증감(②-①)
A13: A1 | B13: 잔존만기 3개월이내 유동성자산(A) | C13: 3403279526 | D13: 3312916231 | E13: =D13-C13 -> -90363295
A14: _x000D_ A2 | B14: 잔존만기 3개월이내 유동성부채(B) | C14: 52058612 | D14: 25382713 | E14: =D14-C14 -> -26675899
A15: _x000D_ A3 | B15: 유동성비율=(A/B)×100 | C15: =C13/C14 -> 65.373997 | D15: =D13/D14 -> 130.5186 | E15: =D15-C15 -> 65.144606

Sheet GA234(자금조달)
A3: 가. 자금조달 및 운용현황
C11: A | D11: B | E11: C
B12: 계정명 | C12: 월평잔 | D12: 월말잔 | E12: 거래금액
A13: A10000 | B13: 조달(부채와 자본총계) | C13: =SUM(C14:C51) -> 3948922 | D13: =SUM(D14:D51) -> 0 | E13: =SUM(E14:E51) -> 0 | F13: 1
A14: _x000D_ A10100 | B14: 예수부채 | C14: 0 | D14: 0 | E14: 0
A15: _x000D_ A10110 | B15: (위탁자예수금) | C15: 0 | D15: 0 | E15: 0
A16: _x000D_ A10120 | B16: (장내파생상품거래예수금) | C16: 0 | D16: 0 | E16: 0
A17: _x000D_ A10130 | B17: (집합투자증권투자자예수금) | C17: 0 | D17: 0 | E17: 0
A18: _x000D_ A10200 | B18: 차입부채 | C18: 0 | D18: 0 | E18: 0
A19: _x000D_ A10210 | B19: 콜머니 | C19: 0 | D19: 0 | E19: 0
A20: _x000D_ A10211 | B20: 담보 | C20: 0 | D20: 0 | E20: 0
A21: _x000D_ A10212 | B21: 신용 | C21: 0 | D21: 0 | E21: 0
A22: _x000D_ A10220 | B22: 차입금 | C22: 0 | D22: 0 | E22: 0
A23: _x000D_ A10221 | B23: 당좌차월 | C23: 0 | D23: 0 | E23: 0
A24: _x000D_ A10222 | B24: 은행차입금 | C24: 0 | D24: 0 | E24: 0
A25: _x000D_ A10223 | B25: 증금차입금 | C25: 0 | D25: 0 | E25: 0
... A48: _x000D_ A10800 | B48: 기타부채 | C48: 0 | D48: 0 | E48: 0
A49: _x000D_ A10810 | B49: (미지급금) | C49: 3948922 | D49: ='GA023(재무)'!B398 -> 0 | E49: 0 | F49: 1
A50: _x000D_ A10820 | B50: (미지급비용) | C50: 0 | D50: 0 | E50: 0
A51: _x000D_ A10900 | B51: 자본총계 | C51: 0 | D51: ='GA023(재무)'!B422 -> 0 | E51: 0
A52: _x000D_ A20000 | B52: 운용(자산총계) | C52: =SUM(C53:C89) -> 598221044 | D52: =SUM(D53:D89) -> 0 | E52: =SUM(E53:E89) -> 0 | F52: 1
A53: _x000D_ A20100 | B53: 현금및현금성자산 | C53: 597695989 | D53: ='GA023(재무)'!B17 -> 0 | E53: 0 | F53: 1
A54: _x000D_ A20200 | B54: 예치금 | C54: 0 | D54: 0 | E54: 0
A55: _x000D_ A20210 | B55: (투자자예탁금별도예치금) | C55: 0 | D55: 0 | E55: 0
A56: _x000D_ A20220 | B56: (장내파생상품거래예치금) | C56: 0 | D56: 0 | E56: 0
A57: _x000D_ A20300 | B57: 당기손익-공정가치측정증권 | C57: 0 | D57: 0 | E57: 0
A58: _x000D_ A20310 | B58: 주식,신주인수권증서 | C58: 0 | D58: 0 | E58: 0
A59: _x000D_ A20320 | B59: 국채,지방채,특수채 | C59: 0 | D59: 0 | E59: 0
A60: _x000D_ A20330 | B60: 회사채 | C60: 0 | D60: 0 | E60: 0
A61: _x000D_ A20340 | B61: 집합투자증권 | C61: 0 | D61: 0 | E61: 0
A62: _x000D_ A20350 | B62: 기업어음증권 | C62: 0 | D62: 0 | E62: 0
A63: _x000D_ A20360 | B63: 외화증권 | C63: 0 | D63: 0 | E63: 0
A64: _x000D_ A20370 | B64: 기타 | C64: 0 | D64: 0 | E64: 0
A65: _x000D_ A20400 | B65: 기타포괄손익-공정가치측정증권 | C65: 0 | D65: 0 | E65: 0
... A83: _x000D_ A20960 | B83: 기타 | C83: 0 | D83: 0 | E83: 0
A84: _x000D_ A21000 | B84: 유형자산 | C84: 3000 | D84: ='GA023(재무)'!B185 -> 0 | E84: 0 | F84: 1
A85: _x000D_ A21100 | B85: CMA운용자산(종금계정) | C85: 0 | D85: 0 | E85: 0
A86: _x000D_ A21300 | B86: 리스자산(종금계정) | C86: 0 | D86: 0 | E86: 0
A87: _x000D_ A21200 | B87: 기타자산 | C87: 0 | D87: 0 | E87: 0
A88: _x000D_ A21210 | B88: (미수금) | C88: 522055 | D88: ='GA023(재무)'!B217 -> 0 | E88: 0
...
